Workbook
Name ВстроеннаяВременнаяШкала_Дата_начала: #N/A
Name Срез_Скважина: #N/A
Name Срез_Этап: #N/A

Sheet Планы работ
L17: План работ по скважине №851 (к.п. №26) – стандартная форма
L18: Скважина | M18: ОК | N18: Этап | O18: Контекст простоя | P18: Событие | Q18: Категория работ | R18: Вид работ | S18: Категория объектов | T18: Объект работ | U18: Рейс | V18: Описание (кратко) | W18: Часы (план)
L19: 851 | N19: ДПМ | O19: Штатно | Q19: ПР | R19: Передвижка | S19: Оборудование | T19: УПА | V19: Переезд бригады на скв. №851, расстановка оборудования | W19: 3.5
L20: 851 | N20: ПР | O20: Штатно | Q20: Вспом_работы | R20: Завоз | S20: Объекты_промывка_СО | T20: Тех. вода | V20: Набор тех. воды со скв. №858 (V=66,2 м³), обработка ПАВ 0,03% | W20: 10
L21: 851 | N21: ПР | O21: Штатно | Q21: Контроль_замер | R21: Опрессовка | S21: Объекты_устье | T21: Фонтанная арматура | V21: Опрессовка лифта НКТП на 6 МПа и обратного клапана ФА на 4 МПа (негерметично). Демонтаж оборудования КИПа, метанольных линий | W21: 0.77
L22: 851 | N22: ПР | O22: Штатно | Q22: Циркуляция | R22: Обратная промывка | S22: Скважина_ствол | T22: Скважина | V22: Глушение скважины обратной промывкой 1,01 г/см³, Q=7 л/с, V=21 м³ (продолжение) | W22: 5
L23: 851 | N23: ПР | O23: Штатно | Q23: Циркуляция | R23: Обратная промывка | S23: Скважина_ствол | T23: Скважина | V23: Глушение обратной промывкой 1,01 г/см³, V=35 м³ (общ. 56,2 м³), рост давления до 10 МПа. Техотстой 3 ч, разрядка с 4 до 0 МПа, выход конденсата+газ | W23: 8
L24: 851 | N24: ПР | O24: Штатно | Q24: Монтаж_демонтаж_установка | R24: Монтаж | S24: Оборудование | T24: УПА | V24: Монтаж УПРС-80 (30%). Подвоз грунта, отсыпка под приёмный мост и 3 стеллажа | W24: 6
L25: 851 | N25: ПР | O25: Штатно | Q25: Монтаж_демонтаж_установка | R25: Монтаж | S25: Оборудование | T25: УПА | V25: Монтаж УПРС-80 (90%). Долив скважины V=0,5 м³ (общий долив 3 м³) | W25: 2.1
L26: 851 | N26: ПР | O26: Штатно | Q26: Монтаж_демонтаж_установка | R26: Демонтаж | S26: Объекты_устье | T26: Фонтанная арматура | V26: Получение разрешения на демонтаж ФА, монтаж ПВО. Подрыв ПШ (G=43 тн). Демонтаж КВ, протаскивание кабеля, демонтаж ФА | W26: 2.29
L27: 851 | N27: КРС | O27: Штатно | Q27: Монтаж_демонтаж_установка | R27: Монтаж | S27: Объекты_устье | T27: ПВО | V27: Монтаж 2 отбойных щитов, штурвалов, подключение СУП, монтаж выносного пульта, монтаж ПВО (100%) | W27: 1.35
L28: 851 | N28: КРС | O28: Штатно | Q28: СПО | R28: Спуск | S28: Технологический_инструмент | T28: Пакер | V28: Спуск пакера на глубину 30 м. Подготовка к опрессовке ПВО | W28: 0.97
L29: 851 | N29: КРС | O29: Орг_простой | Q29: Простой | R29: Ожидание | S29: Орг_логист_объекты | T29: Техника | V29: Ожидание спецтехники (ЦА-320) для опрессовки | W29: 4
L30: 851 | N30: КРС | O30: Штатно | Q30: Контроль_замер | R30: Опрессовка | S30: Объекты_устье | T30: ПВО | V30: Опрессовка трубных плашек 73 мм с представителем ВСВЧ на 23 МПа (+). Получение разрешения на дальнейшие работы | W30: 6
... L32: 851 | N32: КРС | O32: Штатно | Q32: Циркуляция | R32: Обратная промывка | S32: Скважина_ствол | T32: Скважина | V32: Подготовка к промывке. Обратная промывка раствором 1,01 г/см³ V=37,5 м³, Р=0→10→50 МПа, Q=7 л/с, циркуляция (+). Разрядка (+). Подготовка к подъёму ЭЦН | W32: 0.77
L33: 851 | N33: КРС | O33: Штатно | Q33: СПО | R33: Подъем | S33: Технологический_инструмент | T33: УЭЦН | U33: 1 | V33: Подъём ЭЦН с 2859,88 м до 2600 м (20 шт НКТП-73 мм). Долив 3 м³ | W33: 4
L34: 851 | N34: КРС | O34: Штатно | Q34: СПО | R34: Подъем | S34: Технологический_инструмент | T34: УЭЦН | U34: 1 | V34: Подъём ЭЦН с 2600 м до 1819 м (106 шт, всего 80 шт? уточнение: общее количество поднятых 80 шт – возможно опечатка, оставим как есть). Долив 2 м³ | W34: 8
L35: 851 | N35: КРС | O35: Штатно | Q35: СПО | R35: Подъем | S35: Технологический_инструмент | T35: УЭЦН | U35: 1 | V35: Подъём ЭЦН с 1819 м до 1365 м, ВИК первого ряда. Поднято 156 шт НКТП-73 мм. Долив 30 м³ | W35: 7
L36: 851 | N36: КРС | O36: Штатно | Q36: СПО | R36: Подъем | S36: Технологический_инструмент | T36: УЭЦН | U36: 1 | V36: Подъём ЭЦН с 1365 м до 672,31 м, ВИК 228-229, опрессовка лифта 6 МПа (+), замер изоляции (отсутствует), сброс спецштанги Ø25 мм L=1,2 м (+). Подъём до 0 м | W36: 4.44
L37: 851 | N37: КРС | O37: Штатно | Q37: Сборка_разборка_оснащение | R37: Разборка | S37: Технологический_инструмент | T37: УЭЦН | V37: Комиссионный демонтаж ЭЦН | W37: 2.5
L38: 851 | N38: КРС | O38: Штатно | Q38: Вспом_работы | R38: Подготовка | S38: Технологический_инструмент | T38: УЭЦН | V38: Центровка мачты, разгрузка оборудования ЭЦН, подготовка к опрессовке подклапанных НКТП-73 (6 шт.) | W38: 0.9
L39: 851 | N39: КРС | O39: Штатно | Q39: Контроль_замер | R39: Опрессовка | S39: Технологический_инструмент | T39: УЭЦН | V39: Опрессовка подклапанных НКТ-73 (6 шт.) на 25 МПа (+). Монтаж доп. оборудования + ЭЦН (ЭЦНМТ5-80/2260/8ЭДРТ-56-117) | W39: 6
L40: 851 | N40: КРС | O40: Штатно | Q40: СПО | R40: Спуск | S40: Технологический_инструмент | T40: УЭЦН | U40: 1 | V40: Спуск ЭЦН до глубины 877,66 м (92 шт НКТП-73 мм). Долив 38,3 м³ | W40: 14.5
L41: 851 | N41: КРС | O41: Штатно | Q41: СПО | R41: Спуск | S41: Технологический_инструмент | T41: УЭЦН | U41: 1 | V41: Спуск ЭЦН до 1532,37 м (всего 160 шт). Опрессовка лифта через 600 м (6 МПа). Долив 40 м³ | W41: 8
L42: 851 | N42: КРС | O42: Штатно | Q42: СПО | R42: Спуск | S42: Технологический_инструмент | T42: УЭЦН | U42: 1 | V42: Спуск ЭЦН до 1933,38 м (всего 202 шт). Долив 59 м³ | W42: 4
L43: 851 | N43: КРС | O43: Штатно | Q43: СПО | R43: Спуск | S43: Технологический_инструмент | T43: УЭЦН | U43: 1 | V43: Спуск ЭЦН до 2226 м (всего 232 шт). Долив 62 м³ | W43: 0.5
L44: 851 | N44: КРС | O44: Штатно | Q44: Ремонт | R44: Ремонт | S44: Оборудование | T44: УПА | V44: Ремонт УБРСП-80 (замена ремня компрессора) | W44: 0
L45: 851 | N45: Заканчивание | O45: Штатно | Q45: Монтаж_демонтаж_установка | R45: Перемонтаж | S45: Объекты_устье | T45: Фонтанная арматура | V45: Демонтаж ГКШ-1500, СУ-80, отбойных щитов, штурвалов, линии долива. Демонтаж ПВО с протаскиванием кабеля (35 м). Монтаж ФА и кабельного ввода, опрессовка КВ на 11 МПа. Монтаж обвязки ФА. Укладка кабеля (35 м). Контрольный замер изоляции | W45: 4.5
L46: 851 | N46: ДПМ | O46: Штатно | Q46: Монтаж_демонтаж_установка | R46: Демонтаж | S46: Оборудование | T46: УПА | V46: Демонтаж РП, ИВЭ-50 | W46: 1.5
L47: 851 | N47: Заканчивание | O47: Штатно | Q47: Контроль_замер | R47: Опрессовка | S47: Объекты_устье | T47: Фонтанная арматура | V47: Опрессовка ОК ФА и обвязки на 4 МПа (герметично), опрессовка лифта НКТП на 6 МПа (герметично) | W47: 0.9
L48: 851 | N48: Заканчивание | O48: Штатно | Q48: Испытания | R48: Запуск в работу | S48: Технологический_инструмент | T48: УЭЦН | V48: Замер изоляции перед запуском (200 МОм). Запуск ЭЦНМТ5-80/2260/8ЭДРТ-56-117, параметры: Iпуск=19,8А, Iраб=18,2А, 40Гц, загрузка 41%, Рпр=181 атм, Tпр=75°С, дебит 115 м³/сут | W48: 0.5
L49: 851 | N49: ДПМ | O49: Штатно | Q49: Монтаж_демонтаж_установка | R49: Демонтаж | S49: Оборудование | T49: УПА | V49: Демонтаж УБРСП-80, пригрузов, якорей, приёмного моста, стеллажей. Монтаж дублирующей ЗД №2, опрессовка фланца | W49: 3
L50: 851 | N50: ДПМ | O50: Штатно | Q50: Монтаж_демонтаж_установка | R50: Демонтаж | S50: Оборудование | T50: БО | V50: Демонтаж 1 защитного колпака, монтаж 2 лубрикаторных площадок | W50: 2
L51: 851 | N51: ДПМ | O51: Штатно | Q51: Монтаж_демонтаж_установка | R51: Демонтаж | S51: Оборудование | T51: БО | V51: Демонтаж заземлений (9 шт.), отключение оборудования (4 шт.), демонтаж подставок под кабель (5 шт.), уборка территории | W51: 0.84
L63: План работ по скважине №851 (к.п. №26 КНГКМ) – стандартная форма
L64: ОК | M64: Этап | N64: Контекст простоя | O64: Событие | P64: Категория работ | Q64: Вид работ | R64: Категория объектов | S64: Объект работ | T64: Рейс | U64: Описание | V64: Часы
M65: ДПМ | N65: Штатно | P65: ПР | Q65: Передвижка | R65: Оборудование | S65: УПА | U65: Переезд бригады на скв. №851 (9 рейсов, L=0,015 км) | V65: 0.87
M66: ДПМ | N66: Штатно | P66: Монтаж_демонтаж_установка | Q66: Монтаж | R66: Оборудование | S66: БО | U66: Расстановка оборудования (9 шт.), установка заземлений (9 шт.), подключение (4 шт.), установка подставок под кабель (5 шт.), демонтаж 2‑х лубрикаторных площадок, монтаж 1 защитного колпака | V66: 2.92
M67: ПР | N67: Штатно | P67: Вспом_работы | Q67: Завоз | R67: Объекты_промывка_СО | S67: Тех. вода | U67: Монтаж линии набора воды, набор тех. воды 66,2 м³ (ρ=1,01), обработка ПАВ, отбор пробы. Параллельный завоз жидкости глушения 82 м³ | V67: 10.22
M68: ПР | N68: Штатно | P68: Контроль_замер | Q68: Опрессовка | R68: Объекты_устье | S68: ПВО | U68: Опрессовка превентора с трубными плашками 73 мм до установки на устье (рабочее давление) | V68: 0.36
...

Sheet 0. Лист для печати
E3: Суточный отчет по бурению № | I3: ='2. Для заполнения'!F1 -> 2 | P3: Дата: | Q3: ='2. Для заполнения'!I1 -> 46202
A5: 1. Данные по скважине | J5: 2. Подробная сводка
A6: Месторождение: | C6: ='2. Для заполнения'!D5 -> Казанское | E6: Составил: | F6: ='2. Для заполнения'!G5 -> Воронков Вадим Анатольевич | J6: ="Работы, проводимые в период с 00:00 до 24:00 " & TEXT(Q3-1, "ДД.ММ.ГГГГ") -> Работы, проводимые в период с 00:00 до 24:00 28.06.2026
A7: Куст: | C7: ='2. Для заполнения'!D6 -> 26 | E7: Почта: | F7: ='2. Для заполнения'!G6 -> kazanskoe.project@pobeditholding.com | J7: № п/п | K7: Забой, м | L7: Начало | M7: Конец | N7: Время, ч | O7: Фактические работы
A8: Скважина №: | C8: ='2. Для заполнения'!D7 -> 330 | E8: ОК | F8: Проект, м | G8: Факт, м | H8: Цементаж | J8: =IF('2. Для заполнения'!B36<>" ", '2. Для заполнения'!H36, " ") | K8: ='2. Для заполнения'!B36 | L8: ='2. Для заполнения'!C36 | M8: ='2. Для заполнения'!D36 | N8: ='2. Для заполнения'!E36 | O8: ='2. Для заполнения'!F36
A9: Назначение: | C9: ='2. Для заполнения'!D8 -> Добывающая | E9: 324 | F9: ='2. Для заполнения'!G9 -> 50 | G9: ='2. Для заполнения'!H9 -> 0 | H9: ='2. Для заполнения'!I9
A10: Заказчик: | C10: ='2. Для заполнения'!D9 -> ООО "Газпром Добыча Томск" | E10: 245 | F10: ='2. Для заполнения'!G10 -> 1150.51 | G10: ='2. Для заполнения'!H10 -> 0 | H10: ='2. Для заполнения'!I10 | J10: =IF('2. Для заполнения'!B37<>" ", '2. Для заполнения'!H37, " ") | K10: ='2. Для заполнения'!B37 | L10: ='2. Для заполнения'!C37 | M10: ='2. Для заполнения'!D37 | N10: ='2. Для заполнения'!E37 | O10: ='2. Для заполнения'!F37
A11: Тип БУ: | C11: ='2. Для заполнения'!D10 -> МБУ ZJ-30 | E11: 146 | F11: ='2. Для заполнения'!G11 -> 2491 | G11: ='2. Для заполнения'!H11 -> 0 | H11: ='2. Для заполнения'!I11
A12: Начало бурения: | C12: ='2. Для заполнения'!D14 -> 46145.099 | E12: 102 | F12: ='2. Для заполнения'!G12 -> 3591 | G12: ='2. Для заполнения'!H12 -> 0 | H12: ='2. Для заполнения'!I12 | J12: =IF('2. Для заполнения'!B38<>" ", '2. Для заполнения'!H38, " ") | K12: ='2. Для заполнения'!B38 | L12: ='2. Для заполнения'!C38 | M12: ='2. Для заполнения'!D38 | N12: ='2. Для заполнения'!E38 | O12: ='2. Для заполнения'!F38
A13: Длительность по плану: | C13: ='2. Для заполнения'!D15 -> 7.49625 | D13: Проектная глубина по стволу, м: | G13: ='2. Для заполнения'!G14 -> 3591
A14: Фактически дней: | C14: ='2. Для заполнения'!D16 -> 50.666667 | D14: Проектная глубина (верт), м: | G14: ='2. Для заполнения'!G15 -> 2475 | J14: =IF('2. Для заполнения'!B39<>" ", '2. Для заполнения'!H39, " ") | K14: ='2. Для заполнения'!B39 | L14: ='2. Для заполнения'!C39 | M14: ='2. Для заполнения'!D39 | N14: ='2. Для заполнения'!E39 | O14: ='2. Для заполнения'!F39
A15: Отставание от ГГД: | C15: ='2. Для заполнения'!D17 -> #REF! | D15: Кровля пласта (верт), м: | G15: ='2. Для заполнения'!G16 -> 2469.3
A16: Диаметр ствола: | C16: ='2. Для заполнения'!D19 -> 126 | D16: Тип профиля: | G16: ='2. Для заполнения'!G17 -> Наклонно-направленный | J16: =IF('2. Для заполнения'!B40<>" ", '2. Для заполнения'!H40, " ") | K16: ='2. Для заполнения'!B40 | L16: ='2. Для заполнения'!C40 | M16: ='2. Для заполнения'!D40 | N16: ='2. Для заполнения'!E40 | O16: ='2. Для заполнения'!F40
A17: MD, м: | C17: ='2. Для заполнения'!D20 -> 3538 | D17: Макс. зенитный угол, град: | G17: ='2. Для заполнения'!G18 -> 88,98
A18: TVD, м: | C18: ='2. Для заполнения'!D21 -> 2476.26 | D18: Макс. интенсивность, град/10м: | G18: ='2. Для заполнения'!G19 -> 1,5 | J18: =IF('2. Для заполнения'!B41<>" ", '2. Для заполнения'!H41, " ") | K18: ='2. Для заполнения'!B41 | L18: ='2. Для заполнения'!C41 | M18: ='2. Для заполнения'!D41 | N18: ='2. Для заполнения'!E41 | O18: ='2. Для заполнения'!F41
A19: Суточная проходка: | C19: ='2. Для заполнения'!D22 -> 128 | D19: Смещение от устья, м: | G19: ='2. Для заполнения'!G20 -> 2241.61
A20: Суммарная проходка: | C20: =SUM(Хронология[Проходка, м]) -> 2758.16 | D20: Температура воздуха, °С: | G20: ='2. Для заполнения'!G24 -> -27 | J20: =IF('2. Для заполнения'!B42<>" ", '2. Для заполнения'!H42, " ") | K20: ='2. Для заполнения'!B42 | L20: ='2. Для заполнения'!C42 | M20: ='2. Для заполнения'!D42 | N20: ='2. Для заполнения'!E42 | O20: ='2. Для заполнения'!F42
D21: ПВО испытано (Дата/Давление): | G21: ='2. Для заполнения'!G25 -> 06.02.26г / 35 МПа
D22: ПВО: | G22: ='2. Для заполнения'!G26 -> ОП-5 230х35 | J22: =IF('2. Для заполнения'!B43<>" ", '2. Для заполнения'!H43, " ") | K22: ='2. Для заполнения'!B43 | L22: ='2. Для заполнения'!C43 | M22: ='2. Для заполнения'!D43 | N22: ='2. Для заполнения'!E43 | O22: ='2. Для заполнения'!F43
D23: Наработка тал.каната, т/км: | G23: ='2. Для заполнения'!G27 -> 264,7\264,7
A24: Генеральный подрядчик: | C24: ='2. Для заполнения'!D24 -> ООО "Победит Холдинг" | E24: Долота: | G24: ='2. Для заполнения'!D28 -> ООО "Интер-Сервис" | J24: =IF('2. Для заполнения'!B44<>" ", '2. Для заполнения'!H44, " ") | K24: ='2. Для заполнения'!B44 | L24: ='2. Для заполнения'!C44 | M24: ='2. Для заполнения'!D44 | N24: ='2. Для заполнения'!E44 | O24: ='2. Для заполнения'!F44
A25: Подрядчик по бурению: | C25: ='2. Для заполнения'!D25 -> ООО "Победит Холдинг" | E25: Спуск ОК: | G25: ='2. Для заполнения'!D29 -> ООО "Нефтесервисная компания" "Буран"
A26: Растворы: | C26: ='2. Для заполнения'!D26 -> ООО "НСК Эшелон" | E26: ГИС и ГТК: | G26: ='2. Для заполнения'!D30 -> ПФ «Востокгазгеофизика» | J26: =IF('2. Для заполнения'!B45<>" ", '2. Для заполнения'!H45, " ") | K26: ='2. Для заполнения'!B45 | L26: ='2. Для заполнения'!C45 | M26: ='2. Для заполнения'!D45 | N26: ='2. Для заполнения'!E45 | O26: ='2. Для заполнения'!F45
A27: ННБ: | C27: ='2. Для заполнения'!D27 -> ООО "Интер-Сервис" | E27: Цементирование: | G27: ='2. Для заполнения'!D31 -> ООО "ЦЦС"
J28: =IF('2. Для заполнения'!B46<>" ", '2. Для заполнения'!H46, " ") | K28: ='2. Для заполнения'!B46 | L28: ='2. Для заполнения'!C46 | M28: ='2. Для заполнения'!D46 | N28: ='2. Для заполнения'!E46 | O28: ='2. Для заполнения'!F46
A29: 3. Данные по КНБК (последняя СПО)
A30: Оборудование | B30: Наружный Ø,мм | C30: Внутр. Ø,мм | D30: Длина, м | E30: Σ Длина,м | F30: Серийный номер | G30: Тип и размер соединения | H30: Примечание | J30: =IF('2. Для заполнения'!B47<>" ", '2. Для заполнения'!H47, " ") | K30: ='2. Для заполнения'!B47 | L30: ='2. Для заполнения'!C47 | M30: ='2. Для заполнения'!D47 | N30: ='2. Для заполнения'!E47 | O30: ='2. Для заполнения'!F47
A32: =IF('2. Для заполнения'!B71=0, " ", '2. Для заполнения'!B71) -> PDC TD-126,0 SVD 513-T1 S233 (4х7,9мм; 2х8,2мм) Технодрил | B32: =IF('2. Для заполнения'!D71=0, " ", '2. Для заполнения'!D71) -> 126 | C32: =IF('2. Для заполнения'!E71=0, " ", '2. Для заполнения'!E71) -> 4х7,9мм; 2х8,2мм | D32: =IF('2. Для заполнения'!F71=0, " ", '2. Для заполнения'!F71) -> 0.18 | E32: =IF('2. Для заполнения'!G71=0, " ", '2. Для заполнения'!G71) -> 0.18 | F32: =IF('2. Для заполнения'!H71=0, " ", '2. Для заполнения'!H71) -> 190425 | G32: =IF('2. Для заполнения'!I71=0, " ", '2. Для заполнения'!I71) -> Нз76 | J32: =IF('2. Для заполнения'!B48<>" ", '2. Для заполнения'!H48, " ") | K32: ='2. Для заполнения'!B48 | L32: ='2. Для заполнения'!C48 | M32: ='2. Для заполнения'!D48 | N32: ='2. Для заполнения'!E48 | O32: ='2. Для заполнения'!F48
A33: =IF('2. Для заполнения'!B72=0, " ", '2. Для заполнения'!B72) -> ДВ 106.7.531-Р 7/8 +КОБ (1º51´) ООО "СОКОL" | B33: =IF('2. Для заполнения'!D72=0, " ", '2. Для заполнения'!D72) -> 108 | C33: =IF('2. Для заполнения'!E72=0, " ", '2. Для заполнения'!E72) -> .- | D33: =IF('2. Для заполнения'!F72=0, " ", '2. Для заполнения'!F72) -> 7.61 | E33: =IF('2. Для заполнения'!G72=0, " ", '2. Для заполнения'!G72) -> 7.79 | F33: =IF('2. Для заполнения'!H72=0, " ", '2. Для заполнения'!H72) -> 4249 | G33: =IF('2. Для заполнения'!I72=0, " ", '2. Для заполнения'!I72) -> Мз 86 х Мз 76
A34: =IF('2. Для заполнения'!B73=0, " ", '2. Для заполнения'!B73) -> Переводник Мз 73 х Нз 86 | B34: =IF('2. Для заполнения'!D73=0, " ", '2. Для заполнения'!D73) -> 108 | C34: =IF('2. Для заполнения'!E73=0, " ", '2. Для заполнения'!E73) -> 45 | D34: =IF('2. Для заполнения'!F73=0, " ", '2. Для заполнения'!F73) -> 0.18 | E34: =IF('2. Для заполнения'!G73=0, " ", '2. Для заполнения'!G73) -> 7.97 | F34: =IF('2. Для заполнения'!H73=0, " ", '2. Для заполнения'!H73) -> 67 | G34: =IF('2. Для заполнения'!I73=0, " ", '2. Для заполнения'!I73) -> Мз 73 х Нз 86 | J34: =IF('2. Для заполнения'!B49<>" ", '2. Для заполнения'!H49, " ") | K34: ='2. Для заполнения'!B49 | L34: ='2. Для заполнения'!C49 | M34: ='2. Для заполнения'!D49 | N34: ='2. Для заполнения'!E49 | O34: ='2. Для заполнения'!F49
A35: =IF('2. Для заполнения'!B74=0, " ", '2. Для заполнения'!B74) -> Резистивиметр (пульсатор №723, батареи 1,2,3№1541;1638;1551,ТМС верхняя №129, ТМС нижняя №191, гамма №544, инклинометр №852) | B35: =IF('2. Для заполнения'!D74=0, " ", '2. Для заполнения'!D74) -> 95.2 | C35: =IF('2. Для заполнения'!E74=0, " ", '2. Для заполнения'!E74) -> 31 | D35: =IF('2. Для заполнения'!F74=0, " ", '2. Для заполнения'!F74) -> 9.45 | E35: =IF('2. Для заполнения'!G74=0, " ", '2. Для заполнения'!G74) -> 17.42 | F35: =IF('2. Для заполнения'!H74=0, " ", '2. Для заполнения'!H74) -> 537 | G35: =IF('2. Для заполнения'!I74=0, " ", '2. Для заполнения'!I74) -> Мз 80 х Нз 73
A36: =IF('2. Для заполнения'!B75=0, " ", '2. Для заполнения'!B75) -> УБТН-95 | B36: =IF('2. Для заполнения'!D75=0, " ", '2. Для заполнения'!D75) -> 95 | C36: =IF('2. Для заполнения'!E75=0, " ", '2. Для заполнения'!E75) -> 55.8 | D36: =IF('2. Для заполнения'!F75=0, " ", '2. Для заполнения'!F75) -> 9.25 | E36: =IF('2. Для заполнения'!G75=0, " ", '2. Для заполнения'!G75) -> 26.67 | F36: =IF('2. Для заполнения'!H75=0, " ", '2. Для заполнения'!H75) -> 80362/36598-2 | G36: =IF('2. Для заполнения'!I75=0, " ", '2. Для заполнения'!I75) -> Мз 80 х Нз 80
A37: =IF('2. Для заполнения'!B76=0, " ", '2. Для заполнения'!B76) -> Переводник Мз 86 х Нз 80 | B37: =IF('2. Для заполнения'!D76=0, " ", '2. Для заполнения'!D76) -> 106 | C37: =IF('2. Для заполнения'!E76=0, " ", '2. Для заполнения'!E76) -> 57.6 | D37: =IF('2. Для заполнения'!F76=0, " ", '2. Для заполнения'!F76) -> 0.46 | E37: =IF('2. Для заполнения'!G76=0, " ", '2. Для заполнения'!G76) -> 27.13 | F37: =IF('2. Для заполнения'!H76=0, " ", '2. Для заполнения'!H76) -> 12025*30 | G37: =IF('2. Для заполнения'!I76=0, " ", '2. Для заполнения'!I76) -> Мз 86 х Нз 80 | J37: ="Работы, проводимые в период с 00:00 до 8:00" & " " & TEXT(Q3, "ДД.ММ.ГГГГ") -> Работы, проводимые в период с 00:00 до 8:00 29.06.2026
A38: =IF('2. Для заполнения'!B77=0, " ", '2. Для заполнения'!B77) -> Ф106-С4 | B38: =IF('2. Для заполнения'!D77=0, " ", '2. Для заполнения'!D77) -> 106 | C38: =IF('2. Для заполнения'!E77=0, " ", '2. Для заполнения'!E77) -> .- | D38: =IF('2. Для заполнения'!F77=0, " ", '2. Для заполнения'!F77) -> 0.51 | E38: =IF('2. Для заполнения'!G77=0, " ", '2. Для заполнения'!G77) -> 27.64 | F38: =IF('2. Для заполнения'!H77=0, " ", '2. Для заполнения'!H77) -> 277 | G38: =IF('2. Для заполнения'!I77=0, " ", '2. Для заполнения'!I77) -> Мз 86 х Нз 86 | J38: Начало | K38: Конец | L38: Время, ч | M38: Забой, м | N38: Фактические работы
A39: =IF('2. Для заполнения'!B78=0, " ", '2. Для заполнения'!B78) -> СБТ-88,9х9,35мм (43 свечи) | B39: =IF('2. Для заполнения'!D78=0, " ", '2. Для заполнения'!D78) -> 88.9 | C39: =IF('2. Для заполнения'!E78=0, " ", '2. Для заполнения'!E78) -> 50.8 | D39: =IF('2. Для заполнения'!F78=0, " ", '2. Для заполнения'!F78) -> 788.46 | E39: =IF('2. Для заполнения'!G78=0, " ", '2. Для заполнения'!G78) -> 816.1 | F39: =IF('2. Для заполнения'!H78=0, " ", '2. Для заполнения'!H78) -> 4 | G39: =IF('2. Для заполнения'!I78=0, " ", '2. Для заполнения'!I78) -> Мз 86 х Нз 86 | J39: =IF('2. Для заполнения'!C58="", " ", '2. Для заполнения'!C58) | K39: =IF('2. Для заполнения'!D58="", " ", '2. Для заполнения'!D58) | L39: =IF('2. Для заполнения'!E58="", " ", '2. Для заполнения'!E58) | M39: =IF('2. Для заполнения'!B58=0, " ", '2. Для заполнения'!B58) | N39: =IF('2. Для заполнения'!F58=0, " ", '2. Для заполнения'!F58)
A40: =IF('2. Для заполнения'!B79=0, " ", '2. Для заполнения'!B79) -> ТБТ-К1-108-89-51 (3 свечи) | B40: =IF('2. Для заполнения'!D79=0, " ", '2. Для заполнения'!D79) -> 88.9 | C40: =IF('2. Для заполнения'!E79=0, " ", '2. Для заполнения'!E79) -> 53 | D40: =IF('2. Для заполнения'!F79=0, " ", '2. Для заполнения'!F79) -> 55.18 | E40: =IF('2. Для заполнения'!G79=0, " ", '2. Для заполнения'!G79) -> 871.28 | F40: =IF('2. Для заполнения'!H79=0, " ", '2. Для заполнения'!H79) -> 19 | G40: =IF('2. Для заполнения'!I79=0, " ", '2. Для заполнения'!I79) -> Мз 86 х Нз 86 | J40: =IF('2. Для заполнения'!C59="", " ", '2. Для заполнения'!C59) | K40: =IF('2. Для заполнения'!D59="", " ", '2. Для заполнения'!D59) | L40: =IF('2. Для заполнения'!E59="", " ", '2. Для заполнения'!E59) | M40: =IF('2. Для заполнения'!B59=0, " ", '2. Для заполнения'!B59) | N40: =IF('2. Для заполнения'!F59=0, " ", '2. Для заполнения'!F59)
A41: =IF('2. Для заполнения'!B80=0, " ", '2. Для заполнения'!B80) -> ЯС-106 ГМ | B41: =IF('2. Для заполнения'!D80=0, " ", '2. Для заполнения'!D80) -> 108 | C41: =IF('2. Для заполнения'!E80=0, " ", '2. Для заполнения'!E80) -> 50.8 | D41: =IF('2. Для заполнения'!F80=0, " ", '2. Для заполнения'!F80) -> 5.74 | E41: =IF('2. Для заполнения'!F80=0, " ", '2. Для заполнения'!F80) -> 5.74 | F41: =IF('2. Для заполнения'!H80=0, " ", '2. Для заполнения'!H80) -> 146 | G41: =IF('2. Для заполнения'!I80=0, " ", '2. Для заполнения'!I80) -> Мз 86 х Нз 86 | J41: =IF('2. Для заполнения'!C60="", " ", '2. Для заполнения'!C60) | K41: =IF('2. Для заполнения'!D60="", " ", '2. Для заполнения'!D60) | L41: =IF('2. Для заполнения'!E60="", " ", '2. Для заполнения'!E60) | M41: =IF('2. Для заполнения'!B60=0, " ", '2. Для заполнения'!B60) | N41: =IF('2. Для заполнения'!F60=0, " ", '2. Для заполнения'!F60)
A42: =IF('2. Для заполнения'!B81=0, " ", '2. Для заполнения'!B81) -> ТБТ-К1-108-89-51 (3 свечи) | B42: =IF('2. Для заполнения'!C81=0, " ", '2. Для заполнения'!C81) | C42: =IF('2. Для заполнения'!D81=0, " ", '2. Для заполнения'!D81) -> 88.9 | D42: =IF('2. Для заполнения'!E81=0, " ", '2. Для заполнения'!E81) -> 53 | E42: =IF('2. Для заполнения'!F81=0, " ", '2. Для заполнения'!F81) -> 55.28 | F42: =IF('2. Для заполнения'!G81=0, " ", '2. Для заполнения'!G81) -> 932.3 | G42: =IF('2. Для заполнения'!H81=0, " ", '2. Для заполнения'!H81) -> 19 | H42: =IF('2. Для заполнения'!I81=0, " ", '2. Для заполнения'!I81) -> Мз 86 х Нз 86
A43: =IF('2. Для заполнения'!B82=0, " ", '2. Для заполнения'!B82) -> СБТ-88,9х9,35мм (ост) | B43: =IF('2. Для заполнения'!C82=0, " ", '2. Для заполнения'!C82) | C43: =IF('2. Для заполнения'!D82=0, " ", '2. Для заполнения'!D82) -> 88.9 | D43: =IF('2. Для заполнения'!E82=0, " ", '2. Для заполнения'!E82) -> 50.8 | E43: =IF('2. Для заполнения'!F82=0, " ", '2. Для заполнения'!F82) -> 2658.7 | F43: =IF('2. Для заполнения'!G82=0, " ", '2. Для заполнения'!G82) -> 3591 | G43: =IF('2. Для заполнения'!H82=0, " ", '2. Для заполнения'!H82) -> 4 | H43: =IF('2. Для заполнения'!I82=0, " ", '2. Для заполнения'!I82) -> Мз 86 х Нз 86 | J43: 4. Заявки
A44: =IF('2. Для заполнения'!B83=0, " ", '2. Для заполнения'!B83) | B44: =IF('2. Для заполнения'!C83=0, " ", '2. Для заполнения'!C83) | C44: =IF('2. Для заполнения'!D83=0, " ", '2. Для заполнения'!D83) | D44: =IF('2. Для заполнения'!E83=0, " ", '2. Для заполнения'!E83) | E44: =IF('2. Для заполнения'!F83=0, " ", '2. Для заполнения'!F83) | F44: =IF('2. Для заполнения'!G83=0, " ", '2. Для заполнения'!G83) | G44: =IF('2. Для заполнения'!H83=0, " ", '2. Для заполнения'!H83) | H44: =IF('2. Для заполнения'!I83=0, " ", '2. Для заполнения'!I83) | J44: № п/п | K44: Потребность | P44: Кол-во | Q44: Примечание
...

Sheet 1. Хронология работ
A1: Проект | B1: Основные работы | C1: Месторождение | D1: Куст | E1: Скважина | F1: Мастер | G1: Помощник мастера | H1: Бурильщик | I1: № рапорта | J1: № п/п | K1: ОК | L1: Этап | M1: Контекст простоя | N1: Событие | O1: Категория работ | P1: Вид работ | Q1: Категория объектов | R1: Объект работ | S1: Рейс | T1: Описание работ | U1: Часы | V1: Забой, м | W1: Статус | X1: Ответственный за НПВ | Y1: Слайд/ротор | Z1: G, т | AA1: Q, л/с | AB1: P, атм | AC1: N, об/мин | AD1: M, кН*м | AE1: Проходка, м | AF1: Начало | AG1: Окончание | AH1: Сутки | AI1: Нараст. сутки | AJ1: Результат | AK1: ПВ | AL1: ПНВ | AM1: НПВ | AN1: Накопительное НПВ | AO1: Накопительное ПНВ | AP1: Дата начала | AQ1: Время начала | AR1: Дата окончания | AS1: Время окончания | AT1: Бригада | AU1: Ключ | AV1: Результат, вид, объект | AW1: Подытог за операцию | AX1: Вид, объект
A2: ГДТ | B2: КРС | C2: Казанское | D2: 1 | E2: 6 бис | F2: Вдовин И.О. | H2: Жангазиев С.К. | I2: 1 | J2: 0.1 | L2: ДПМ | M2: Штатно | O2: ПР | P2: Передвижка | Q2: Оборудование | R2: УПА | T2: Переезд бригады на скв. № 6 бис к.п. № 1 бис КНГКМ с к.п. № 7 КНГКМ 9 рейсов L= 7,696км. | U2: 4 | W2: Работы окончены | X2: Победит Холдинг | AE2: =IFERROR(IF(Хронология[[#This Row],[Забой, м]]-V1<0, 0, Хронология[[#This Row],[Забой, м]]-V1), 0) -> 0 | AF2: 46144.833 | AG2: =Хронология[[#This Row],[Начало]]+Хронология[[#This Row],[Сутки]] -> 46145 | AH2: =Хронология[[#This Row],[Часы]]/24 -> 0.16666667 | AI2: =IFERROR(Хронология[[#This Row],[Сутки]]+AI1, Хронология[[#This Row],[Сутки]]) -> 0.16666667 | AJ2: =IF(Хронология[[#This Row],[Этап]]="Доп. работы", "ПВ", IFERROR( IF(AND( MATCH(Хронология[[#This Row],[Ключ]], Планирование[Ключ], 0), Хронология[[#This Row],[Подытог за операцию]] <= INDEX(Планирование[Сутки (план)], MATCH(Хронология[[#This Row],[Ключ]], Планирование[Ключ], 0)) ), "ПВ", "ПНВ"), "НПВ")) -> ПВ | AK2: =IF( OR(Хронология[[#This Row],[Результат]]="ПВ", Хронология[[#This Row],[Результат]]="ПНВ"), Хронология[[#This Row],[Часы]] - IF( Хронология[[#This Row],[Результат]]="ПНВ", MAX(0, MAX(0, SUMIFS(Хронология[Часы], Хронология[Ключ], Хронология[[#This Row],[Ключ]], Хронология[Начало], "<=" & Хронология[[#This Row],[Начало]]) - IFERROR(INDEX(Планирование[Часы (план)], MATCH(Хронология[[#This Row],[Ключ]], Планирование[Ключ], 0)), 0)) - MAX(0, SUMIFS(Хронология[Часы], Хронология[Ключ], Хронология[[#This Row],[Ключ]], Хронология[Начало], "<" & Хронология[[#This Row],[Начало]]) - IFERROR(INDEX(Планирование[Часы (план)], MATCH(Хронология[[#This Row],[Ключ]], Планирование[Ключ], 0)), 0)) ), 0 ), 0 ) -> 4 | AL2: =IF( Хронология[[#This Row],[Результат]]="ПНВ", MAX(0, MAX(0, SUMIFS(Хронология[Часы], Хронология[Ключ], Хронология[[#This Row],[Ключ]], Хронология[Начало], "<=" & Хронология[[#This Row],[Начало]]) - IFERROR(INDEX(Планирование[Часы (план)], MATCH(Хронология[[#This Row],[Ключ]], Планирование[Ключ], 0)), 0)) - MAX(0, SUMIFS(Хронология[Часы], Хронология[Ключ], Хронология[[#This Row],[Ключ]], Хронология[Начало], "<" & Хронология[[#This Row],[Начало]]) - IFERROR(INDEX(Планирование[Часы (план)], MATCH(Хронология[[#This Row],[Ключ]], Планирование[Ключ], 0)), 0)) ), 0 ) -> 0 | AM2: =IF(Хронология[[#This Row],[Результат]]="НПВ", Хронология[[#This Row],[Часы]], 0) -> 0 | AN2: =SUMIFS(Хронология[НПВ], Хронология[Скважина], Хронология[[#This Row],[Скважина]], Хронология[Начало], "<=" & Хронология[[#This Row],[Начало]]) -> 0 | AO2: =SUMIFS(Хронология[ПНВ], Хронология[Скважина], Хронология[[#This Row],[Скважина]], Хронология[Начало], "<=" & Хронология[[#This Row],[Начало]]) -> 0 | AP2: =INT(ROUND(Хронология[[#This Row],[Начало]], 3)) -> 46144 | AQ2: =Хронология[[#This Row],[Начало]]-INT(Хронология[[#This Row],[Начало]]) -> 0.83333333 | AR2: =INT(ROUND(Хронология[[#This Row],[Окончание]], 3)) -> 46145 | AS2: =Хронология[[#This Row],[Окончание]]-INT(Хронология[[#This Row],[Окончание]]) -> 0 | AT2: =Хронология[[#This Row],[Мастер]] & CHAR(10) & Хронология[[#This Row],[Помощник мастера]] & CHAR(10) & Хронология[[#This Row],[Бурильщик]] -> Вдовин И.О. Жангазиев С.К. | AU2: =IF(Хронология[[#This Row],[Контекст простоя]]="Штатно", Хронология[[#This Row],[Скважина]] & " " & "ОК–" &Хронология[[#This Row],[ОК]] & " " & Хронология[[#This Row],[Этап]] & " " & Хронология[[#This Row],[Вид работ]] & " " & Хронология[[#This Row],[Объект работ]] & " " & Хронология[[#This Row],[Рейс]], Хронология[[#This Row],[Скважина]] & " " & "ОК–" &Хронология[[#This Row],[ОК]] & " " & Хронология[[#This Row],[Этап]] & " " & Хронология[[#This Row],[Контекст простоя]] & " " & Хронология[[#This Row],[Событие]] & " " & Хронология[[#This Row],[Вид работ]] & " " & Хронология[[#This Row],[Объект работ]] & " " & Хронология[[#This Row],[Рейс]]) -> 6 бис ОК– ДПМ Передвижка УПА | AV2: =Хронология[[#This Row],[Результат]]&": "&Хронология[[#This Row],[Событие]]& CHAR(10) &Хронология[[#This Row],[Вид работ]]&" "&Хронология[[#This Row],[Объект работ]] -> ПВ: Передвижка УПА | AW2: =SUMIF($AU$2:AU2, Хронология[[#This Row],[Ключ]], $AH$2:AH2) -> 0.16666667 | AX2: =Хронология[[#This Row],[Вид работ]] & " " & Хронология[[#This Row],[Объект работ]] -> Передвижка УПА
A3: ГДТ | B3: КРС | C3: Казанское | D3: 1 | E3: 6 бис | F3: Жабин П.П. | H3: Керимов Н.К. | L3: ДПМ | M3: Штатно | O3: ПР | P3: Передвижка | Q3: Оборудование | R3: УПА | U3: 2.5 | AE3: =IFERROR(IF(Хронология[[#This Row],[Забой, м]]-V2<0, 0, Хронология[[#This Row],[Забой, м]]-V2), 0) -> 0 | AF3: =AG2 -> 46145 | AG3: =Хронология[[#This Row],[Начало]]+Хронология[[#This Row],[Сутки]] -> 46145.104 | AH3: =Хронология[[#This Row],[Часы]]/24 -> 0.10416667 | AI3: =IFERROR(Хронология[[#This Row],[Сутки]]+AI2, Хронология[[#This Row],[Сутки]]) -> 0.27083333 | AJ3: =IF(Хронология[[#This Row],[Этап]]="Доп. работы", "ПВ", IFERROR( IF(AND( MATCH(Хронология[[#This Row],[Ключ]], Планирование[Ключ], 0), Хронология[[#This Row],[Подытог за операцию]] <= INDEX(Планирование[Сутки (план)], MATCH(Хронология[[#This Row],[Ключ]], Планирование[Ключ], 0)) ), "ПВ", "ПНВ"), "НПВ")) -> ПНВ | AK3: =IF( OR(Хронология[[#This Row],[Результат]]="ПВ", Хронология[[#This Row],[Результат]]="ПНВ"), Хронология[[#This Row],[Часы]] - IF( Хронология[[#This Row],[Результат]]="ПНВ", MAX(0, MAX(0, SUMIFS(Хронология[Часы], Хронология[Ключ], Хронология[[#This Row],[Ключ]], Хронология[Начало], "<=" & Хронология[[#This Row],[Начало]]) - IFERROR(INDEX(Планирование[Часы (план)], MATCH(Хронология[[#This Row],[Ключ]], Планирование[Ключ], 0)), 0)) - MAX(0, SUMIFS(Хронология[Часы], Хронология[Ключ], Хронология[[#This Row],[Ключ]], Хронология[Начало], "<" & Хронология[[#This Row],[Начало]]) - IFERROR(INDEX(Планирование[Часы (план)], MATCH(Хронология[[#This Row],[Ключ]], Планирование[Ключ], 0)), 0)) ), 0 ), 0 ) -> 2.37 | AL3: =IF( Хронология[[#This Row],[Результат]]="ПНВ", MAX(0, MAX(0, SUMIFS(Хронология[Часы], Хронология[Ключ], Хронология[[#This Row],[Ключ]], Хронология[Начало], "<=" & Хронология[[#This Row],[Начало]]) - IFERROR(INDEX(Планирование[Часы (план)], MATCH(Хронология[[#This Row],[Ключ]], Планирование[Ключ], 0)), 0)) - MAX(0, SUMIFS(Хронология[Часы], Хронология[Ключ], Хронология[[#This Row],[Ключ]], Хронология[Начало], "<" & Хронология[[#This Row],[Начало]]) - IFERROR(INDEX(Планирование[Часы (план)], MATCH(Хронология[[#This Row],[Ключ]], Планирование[Ключ], 0)), 0)) ), 0 ) -> 0.13 | AM3: =IF(Хронология[[#This Row],[Результат]]="НПВ", Хронология[[#This Row],[Часы]], 0) -> 0 | AN3: =SUMIFS(Хронология[НПВ], Хронология[Скважина], Хронология[[#This Row],[Скважина]], Хронология[Начало], "<=" & Хронология[[#This Row],[Начало]]) -> 0 | AO3: =SUMIFS(Хронология[ПНВ], Хронология[Скважина], Хронология[[#This Row],[Скважина]], Хронология[Начало], "<=" & Хронология[[#This Row],[Начало]]) -> 0.13 | AP3: =INT(ROUND(Хронология[[#This Row],[Начало]], 3)) -> 46145 | AQ3: =Хронология[[#This Row],[Начало]]-INT(Хронология[[#This Row],[Начало]]) -> 0 | AR3: =INT(ROUND(Хронология[[#This Row],[Окончание]], 3)) -> 46145 | AS3: =Хронология[[#This Row],[Окончание]]-INT(Хронология[[#This Row],[Окончание]]) -> 0.10416667 | AT3: =Хронология[[#This Row],[Мастер]] & CHAR(10) & Хронология[[#This Row],[Помощник мастера]] & CHAR(10) & Хронология[[#This Row],[Бурильщик]] -> Жабин П.П. Керимов Н.К. | AU3: =IF(Хронология[[#This Row],[Контекст простоя]]="Штатно", Хронология[[#This Row],[Скважина]] & " " & "ОК–" &Хронология[[#This Row],[ОК]] & " " & Хронология[[#This Row],[Этап]] & " " & Хронология[[#This Row],[Вид работ]] & " " & Хронология[[#This Row],[Объект работ]] & " " & Хронология[[#This Row],[Рейс]], Хронология[[#This Row],[Скважина]] & " " & "ОК–" &Хронология[[#This Row],[ОК]] & " " & Хронология[[#This Row],[Этап]] & " " & Хронология[[#This Row],[Контекст простоя]] & " " & Хронология[[#This Row],[Событие]] & " " & Хронология[[#This Row],[Вид работ]] & " " & Хронология[[#This Row],[Объект работ]] & " " & Хронология[[#This Row],[Рейс]]) -> 6 бис ОК– ДПМ Передвижка УПА | AV3: =Хронология[[#This Row],[Результат]]&": "&Хронология[[#This Row],[Событие]]& CHAR(10) &Хронология[[#This Row],[Вид работ]]&" "&Хронология[[#This Row],[Объект работ]] -> ПНВ: Передвижка УПА | AW3: =SUMIF($AU$2:AU3, Хронология[[#This Row],[Ключ]], $AH$2:AH3) -> 0.27083333 | AX3: =Хронология[[#This Row],[Вид работ]] & " " & Хронология[[#This Row],[Объект работ]] -> Передвижка УПА
A4: ГДТ | B4: КРС | C4: Казанское | D4: 1 | E4: 6 бис | F4: Жабин П.П. | H4: Керимов Н.К. | I4: 1 | J4: 0.2 | L4: ДПМ | M4: Штатно | O4: Монтаж_демонтаж_установка | P4: Монтаж | Q4: Оборудование | R4: БО | T4: Расстановка оборудования- 9шт. Установка заземления - 9шт. Монтаж подставок под кабель-25шт. Подключение оборудования-8шт. Монтаж Экр.колпаков - 1 шт. | U4: 4.25 | W4: Работы окончены | X4: Победит Холдинг | AE4: =IFERROR(IF(Хронология[[#This Row],[Забой, м]]-V3<0, 0, Хронология[[#This Row],[Забой, м]]-V3), 0) -> 0 | AF4: =AG3 -> 46145.104 | AG4: =Хронология[[#This Row],[Начало]]+Хронология[[#This Row],[Сутки]] -> 46145.281 | AH4: =Хронология[[#This Row],[Часы]]/24 -> 0.17708333 | AI4: =IFERROR(Хронология[[#This Row],[Сутки]]+AI3, Хронология[[#This Row],[Сутки]]) -> 0.44791667 | AJ4: =IF(Хронология[[#This Row],[Этап]]="Доп. работы", "ПВ", IFERROR( IF(AND( MATCH(Хронология[[#This Row],[Ключ]], Планирование[Ключ], 0), Хронология[[#This Row],[Подытог за операцию]] <= INDEX(Планирование[Сутки (план)], MATCH(Хронология[[#This Row],[Ключ]], Планирование[Ключ], 0)) ), "ПВ", "ПНВ"), "НПВ")) -> ПНВ | AK4: =IF( OR(Хронология[[#This Row],[Результат]]="ПВ", Хронология[[#This Row],[Результат]]="ПНВ"), Хронология[[#This Row],[Часы]] - IF( Хронология[[#This Row],[Результат]]="ПНВ", MAX(0, MAX(0, SUMIFS(Хронология[Часы], Хронология[Ключ], Хронология[[#This Row],[Ключ]], Хронология[Начало], "<=" & Хронология[[#This Row],[Начало]]) - IFERROR(INDEX(Планирование[Часы (план)], MATCH(Хронология[[#This Row],[Ключ]], Планирование[Ключ], 0)), 0)) - MAX(0, SUMIFS(Хронология[Часы], Хронология[Ключ], Хронология[[#This Row],[Ключ]], Хронология[Начало], "<" & Хронология[[#This Row],[Начало]]) - IFERROR(INDEX(Планирование[Часы (план)], MATCH(Хронология[[#This Row],[Ключ]], Планирование[Ключ], 0)), 0)) ), 0 ), 0 ) -> 4.04 | AL4: =IF( Хронология[[#This Row],[Результат]]="ПНВ", MAX(0, MAX(0, SUMIFS(Хронология[Часы], Хронология[Ключ], Хронология[[#This Row],[Ключ]], Хронология[Начало], "<=" & Хронология[[#This Row],[Начало]]) - IFERROR(INDEX(Планирование[Часы (план)], MATCH(Хронология[[#This Row],[Ключ]], Планирование[Ключ], 0)), 0)) - MAX(0, SUMIFS(Хронология[Часы], Хронология[Ключ], Хронология[[#This Row],[Ключ]], Хронология[Начало], "<" & Хронология[[#This Row],[Начало]]) - IFERROR(INDEX(Планирование[Часы (план)], MATCH(Хронология[[#This Row],[Ключ]], Планирование[Ключ], 0)), 0)) ), 0 ) -> 0.21 | AM4: =IF(Хронология[[#This Row],[Результат]]="НПВ", Хронология[[#This Row],[Часы]], 0) -> 0 | AN4: =SUMIFS(Хронология[НПВ], Хронология[Скважина], Хронология[[#This Row],[Скважина]], Хронология[Начало], "<=" & Хронология[[#This Row],[Начало]]) -> 0 | AO4: =SUMIFS(Хронология[ПНВ], Хронология[Скважина], Хронология[[#This Row],[Скважина]], Хронология[Начало], "<=" & Хронология[[#This Row],[Начало]]) -> 0.34 | AP4: =INT(ROUND(Хронология[[#This Row],[Начало]], 3)) -> 46145 | AQ4: =Хронология[[#This Row],[Начало]]-INT(Хронология[[#This Row],[Начало]]) -> 0.10416667 | AR4: =INT(ROUND(Хронология[[#This Row],[Окончание]], 3)) -> 46145 | AS4: =Хронология[[#This Row],[Окончание]]-INT(Хронология[[#This Row],[Окончание]]) -> 0.28125 | AT4: =Хронология[[#This Row],[Мастер]] & CHAR(10) & Хронология[[#This Row],[Помощник мастера]] & CHAR(10) & Хронология[[#This Row],[Бурильщик]] -> Жабин П.П. Керимов Н.К. | AU4: =IF(Хронология[[#This Row],[Контекст простоя]]="Штатно", Хронология[[#This Row],[Скважина]] & " " & "ОК–" &Хронология[[#This Row],[ОК]] & " " & Хронология[[#This Row],[Этап]] & " " & Хронология[[#This Row],[Вид работ]] & " " & Хронология[[#This Row],[Объект работ]] & " " & Хронология[[#This Row],[Рейс]], Хронология[[#This Row],[Скважина]] & " " & "ОК–" &Хронология[[#This Row],[ОК]] & " " & Хронология[[#This Row],[Этап]] & " " & Хронология[[#This Row],[Контекст простоя]] & " " & Хронология[[#This Row],[Событие]] & " " & Хронология[[#This Row],[Вид работ]] & " " & Хронология[[#This Row],[Объект работ]] & " " & Хронология[[#This Row],[Рейс]]) -> 6 бис ОК– ДПМ Монтаж БО | AV4: =Хронология[[#This Row],[Результат]]&": "&Хронология[[#This Row],[Событие]]& CHAR(10) &Хронология[[#This Row],[Вид работ]]&" "&Хронология[[#This Row],[Объект работ]] -> ПНВ: Монтаж БО | AW4: =SUMIF($AU$2:AU4, Хронология[[#This Row],[Ключ]], $AH$2:AH4) -> 0.17708333 | AX4: =Хронология[[#This Row],[Вид работ]] & " " & Хронология[[#This Row],[Объект работ]] -> Монтаж БО
A5: ГДТ | B5: КРС | C5: Казанское | D5: 1 | E5: 6 бис | F5: Вдовин И.О. | H5: Жангазиев С.К. | I5: 1 | J5: 0.3 | L5: ПР | M5: Штатно | O5: Монтаж_демонтаж_установка | P5: Монтаж | Q5: Оборудование | R5: УПА | T5: Монтаж подъемного агрегата А-60/80 согласно ТУ и правил ПБ - 100%, РП, спайдера СУ-80, гидроключа ГКШ-1200, ИВЭ-50. Монтаж системы видеонаблюдения. Устройство 2-х якорей. Установка пригрузов 2-х комплектов. Монтаж ПМ и трёх облегченных стеллажей. | U5: 11.25 | W5: Работы окончены | X5: Победит Холдинг | AE5: =IFERROR(IF(Хронология[[#This Row],[Забой, м]]-V4<0, 0, Хронология[[#This Row],[Забой, м]]-V4), 0) -> 0 | AF5: =AG4 -> 46145.281 | AG5: =Хронология[[#This Row],[Начало]]+Хронология[[#This Row],[Сутки]] -> 46145.75 | AH5: =Хронология[[#This Row],[Часы]]/24 -> 0.46875 | AI5: =IFERROR(Хронология[[#This Row],[Сутки]]+AI4, Хронология[[#This Row],[Сутки]]) -> 0.91666667 | AJ5: =IF(Хронология[[#This Row],[Этап]]="Доп. работы", "ПВ", IFERROR( IF(AND( MATCH(Хронология[[#This Row],[Ключ]], Планирование[Ключ], 0), Хронология[[#This Row],[Подытог за операцию]] <= INDEX(Планирование[Сутки (план)], MATCH(Хронология[[#This Row],[Ключ]], Планирование[Ключ], 0)) ), "ПВ", "ПНВ"), "НПВ")) -> ПНВ | AK5: =IF( OR(Хронология[[#This Row],[Результат]]="ПВ", Хронология[[#This Row],[Результат]]="ПНВ"), Хронология[[#This Row],[Часы]] - IF( Хронология[[#This Row],[Результат]]="ПНВ", MAX(0, MAX(0, SUMIFS(Хронология[Часы], Хронология[Ключ], Хронология[[#This Row],[Ключ]], Хронология[Начало], "<=" & Хронология[[#This Row],[Начало]]) - IFERROR(INDEX(Планирование[Часы (план)], MATCH(Хронология[[#This Row],[Ключ]], Планирование[Ключ], 0)), 0)) - MAX(0, SUMIFS(Хронология[Часы], Хронология[Ключ], Хронология[[#This Row],[Ключ]], Хронология[Начало], "<" & Хронология[[#This Row],[Начало]]) - IFERROR(INDEX(Планирование[Часы (план)], MATCH(Хронология[[#This Row],[Ключ]], Планирование[Ключ], 0)), 0)) ), 0 ), 0 ) -> 8.09 | AL5: =IF( Хронология[[#This Row],[Результат]]="ПНВ", MAX(0, MAX(0, SUMIFS(Хронология[Часы], Хронология[Ключ], Хронология[[#This Row],[Ключ]], Хронология[Начало], "<=" & Хронология[[#This Row],[Начало]]) - IFERROR(INDEX(Планирование[Часы (план)], MATCH(Хронология[[#This Row],[Ключ]], Планирование[Ключ], 0)), 0)) - MAX(0, SUMIFS(Хронология[Часы], Хронология[Ключ], Хронология[[#This Row],[Ключ]], Хронология[Начало], "<" & Хронология[[#This Row],[Начало]]) - IFERROR(INDEX(Планирование[Часы (план)], MATCH(Хронология[[#This Row],[Ключ]], Планирование[Ключ], 0)), 0)) ), 0 ) -> 3.16 | AM5: =IF(Хронология[[#This Row],[Результат]]="НПВ", Хронология[[#This Row],[Часы]], 0) -> 0 | AN5: =SUMIFS(Хронология[НПВ], Хронология[Скважина], Хронология[[#This Row],[Скважина]], Хронология[Начало], "<=" & Хронология[[#This Row],[Начало]]) -> 0 | AO5: =SUMIFS(Хронология[ПНВ], Хронология[Скважина], Хронология[[#This Row],[Скважина]], Хронология[Начало], "<=" & Хронология[[#This Row],[Начало]]) -> 3.5 | AP5: =INT(ROUND(Хронология[[#This Row],[Начало]], 3)) -> 46145 | AQ5: =Хронология[[#This Row],[Начало]]-INT(Хронология[[#This Row],[Начало]]) -> 0.28125 | AR5: =INT(ROUND(Хронология[[#This Row],[Окончание]], 3)) -> 46145 | AS5: =Хронология[[#This Row],[Окончание]]-INT(Хронология[[#This Row],[Окончание]]) -> 0.75 | AT5: =Хронология[[#This Row],[Мастер]] & CHAR(10) & Хронология[[#This Row],[Помощник мастера]] & CHAR(10) & Хронология[[#This Row],[Бурильщик]] -> Вдовин И.О. Жангазиев С.К. | AU5: =IF(Хронология[[#This Row],[Контекст простоя]]="Штатно", Хронология[[#This Row],[Скважина]] & " " & "ОК–" &Хронология[[#This Row],[ОК]] & " " & Хронология[[#This Row],[Этап]] & " " & Хронология[[#This Row],[Вид работ]] & " " & Хронология[[#This Row],[Объект работ]] & " " & Хронология[[#This Row],[Рейс]], Хронология[[#This Row],[Скважина]] & " " & "ОК–" &Хронология[[#This Row],[ОК]] & " " & Хронология[[#This Row],[Этап]] & " " & Хронология[[#This Row],[Контекст простоя]] & " " & Хронология[[#This Row],[Событие]] & " " & Хронология[[#This Row],[Вид работ]] & " " & Хронология[[#This Row],[Объект работ]] & " " & Хронология[[#This Row],[Рейс]]) -> 6 бис ОК– ПР Монтаж УПА | AV5: =Хронология[[#This Row],[Результат]]&": "&Хронология[[#This Row],[Событие]]& CHAR(10) &Хронология[[#This Row],[Вид работ]]&" "&Хронология[[#This Row],[Объект работ]] -> ПНВ: Монтаж УПА | AW5: =SUMIF($AU$2:AU5, Хронология[[#This Row],[Ключ]], $AH$2:AH5) -> 0.46875 | AX5: =Хронология[[#This Row],[Вид работ]] & " " & Хронология[[#This Row],[Объект работ]] -> Монтаж УПА
A6: ГДТ | B6: КРС | C6: Казанское | D6: 1 | E6: 6 бис | F6: Вдовин И.О. | H6: Жангазиев С.К. | I6: 1 | J6: 0.4 | L6: ПР | M6: Орг_простой | N6: Ожидание разрешения | O6: Вспом_работы | P6: Устранение | Q6: Орг_логист_объекты | R6: Предписания | T6: Запуск бригады КРС пусковой комиссией. | U6: 6 | W6: Работы окончены | X6: Организационные | AE6: =IFERROR(IF(Хронология[[#This Row],[Забой, м]]-V5<0, 0, Хронология[[#This Row],[Забой, м]]-V5), 0) -> 0 | AF6: =AG5 -> 46145.75 | AG6: =Хронология[[#This Row],[Начало]]+Хронология[[#This Row],[Сутки]] -> 46146 | AH6: =Хронология[[#This Row],[Часы]]/24 -> 0.25 | AI6: =IFERROR(Хронология[[#This Row],[Сутки]]+AI5, Хронология[[#This Row],[Сутки]]) -> 1.1666667 | AJ6: =IF(Хронология[[#This Row],[Этап]]="Доп. работы", "ПВ", IFERROR( IF(AND( MATCH(Хронология[[#This Row],[Ключ]], Планирование[Ключ], 0), Хронология[[#This Row],[Подытог за операцию]] <= INDEX(Планирование[Сутки (план)], MATCH(Хронология[[#This Row],[Ключ]], Планирование[Ключ], 0)) ), "ПВ", "ПНВ"), "НПВ")) -> НПВ | AK6: =IF( OR(Хронология[[#This Row],[Результат]]="ПВ", Хронология[[#This Row],[Результат]]="ПНВ"), Хронология[[#This Row],[Часы]] - IF( Хронология[[#This Row],[Результат]]="ПНВ", MAX(0, MAX(0, SUMIFS(Хронология[Часы], Хронология[Ключ], Хронология[[#This Row],[Ключ]], Хронология[Начало], "<=" & Хронология[[#This Row],[Начало]]) - IFERROR(INDEX(Планирование[Часы (план)], MATCH(Хронология[[#This Row],[Ключ]], Планирование[Ключ], 0)), 0)) - MAX(0, SUMIFS(Хронология[Часы], Хронология[Ключ], Хронология[[#This Row],[Ключ]], Хронология[Начало], "<" & Хронология[[#This Row],[Начало]]) - IFERROR(INDEX(Планирование[Часы (план)], MATCH(Хронология[[#This Row],[Ключ]], Планирование[Ключ], 0)), 0)) ), 0 ), 0 ) -> 0 | AL6: =IF( Хронология[[#This Row],[Результат]]="ПНВ", MAX(0, MAX(0, SUMIFS(Хронология[Часы], Хронология[Ключ], Хронология[[#This Row],[Ключ]], Хронология[Начало], "<=" & Хронология[[#This Row],[Начало]]) - IFERROR(INDEX(Планирование[Часы (план)], MATCH(Хронология[[#This Row],[Ключ]], Планирование[Ключ], 0)), 0)) - MAX(0, SUMIFS(Хронология[Часы], Хронология[Ключ], Хронология[[#This Row],[Ключ]], Хронология[Начало], "<" & Хронология[[#This Row],[Начало]]) - IFERROR(INDEX(Планирование[Часы (план)], MATCH(Хронология[[#This Row],[Ключ]], Планирование[Ключ], 0)), 0)) ), 0 ) -> 0 | AM6: =IF(Хронология[[#This Row],[Результат]]="НПВ", Хронология[[#This Row],[Часы]], 0) -> 6 | AN6: =SUMIFS(Хронология[НПВ], Хронология[Скважина], Хронология[[#This Row],[Скважина]], Хронология[Начало], "<=" & Хронология[[#This Row],[Начало]]) -> 6 | AO6: =SUMIFS(Хронология[ПНВ], Хронология[Скважина], Хронология[[#This Row],[Скважина]], Хронология[Начало], "<=" & Хронология[[#This Row],[Начало]]) -> 3.5 | AP6: =INT(ROUND(Хронология[[#This Row],[Начало]], 3)) -> 46145 | AQ6: =Хронология[[#This Row],[Начало]]-INT(Хронология[[#This Row],[Начало]]) -> 0.75 | AR6: =INT(ROUND(Хронология[[#This Row],[Окончание]], 3)) -> 46146 | AS6: =Хронология[[#This Row],[Окончание]]-INT(Хронология[[#This Row],[Окончание]]) -> 0 | AT6: =Хронология[[#This Row],[Мастер]] & CHAR(10) & Хронология[[#This Row],[Помощник мастера]] & CHAR(10) & Хронология[[#This Row],[Бурильщик]] -> Вдовин И.О. Жангазиев С.К. | AU6: =IF(Хронология[[#This Row],[Контекст простоя]]="Штатно", Хронология[[#This Row],[Скважина]] & " " & "ОК–" &Хронология[[#This Row],[ОК]] & " " & Хронология[[#This Row],[Этап]] & " " & Хронология[[#This Row],[Вид работ]] & " " & Хронология[[#This Row],[Объект работ]] & " " & Хронология[[#This Row],[Рейс]], Хронология[[#This Row],[Скважина]] & " " & "ОК–" &Хронология[[#This Row],[ОК]] & " " & Хронология[[#This Row],[Этап]] & " " & Хронология[[#This Row],[Контекст простоя]] & " " & Хронология[[#This Row],[Событие]] & " " & Хронология[[#This Row],[Вид работ]] & " " & Хронология[[#This Row],[Объект работ]] & " " & Хронология[[#This Row],[Рейс]]) -> 6 бис ОК– ПР Орг_простой Ожидание разрешения Устранение Предписания | AV6: =Хронология[[#This Row],[Результат]]&": "&Хронология[[#This Row],[Событие]]& CHAR(10) &Хронология[[#This Row],[Вид работ]]&" "&Хронология[[#This Row],[Объект работ]] -> НПВ: Ожидание разрешения Устранение Предписания | AW6: =SUMIF($AU$2:AU6, Хронология[[#This Row],[Ключ]], $AH$2:AH6) -> 0.25 | AX6: =Хронология[[#This Row],[Вид работ]] & " " & Хронология[[#This Row],[Объект работ]] -> Устранение Предписания
A7: ГДТ | B7: КРС | C7: Казанское | D7: 1 | E7: 6 бис | F7: Жабин П.П. | H7: Керимов Н.К. | L7: ПР | M7: Орг_простой | N7: Ожидание разрешения | O7: Вспом_работы | P7: Устранение | Q7: Орг_логист_объекты | R7: Предписания | U7: 3 | W7: Работы окончены | X7: Организационные | AE7: =IFERROR(IF(Хронология[[#This Row],[Забой, м]]-V6<0, 0, Хронология[[#This Row],[Забой, м]]-V6), 0) -> 0 | AF7: =AG6 -> 46146 | AG7: =Хронология[[#This Row],[Начало]]+Хронология[[#This Row],[Сутки]] -> 46146.125 | AH7: =Хронология[[#This Row],[Часы]]/24 -> 0.125 | AI7: =IFERROR(Хронология[[#This Row],[Сутки]]+AI6, Хронология[[#This Row],[Сутки]]) -> 1.2916667 | AJ7: =IF(Хронология[[#This Row],[Этап]]="Доп. работы", "ПВ", IFERROR( IF(AND( MATCH(Хронология[[#This Row],[Ключ]], Планирование[Ключ], 0), Хронология[[#This Row],[Подытог за операцию]] <= INDEX(Планирование[Сутки (план)], MATCH(Хронология[[#This Row],[Ключ]], Планирование[Ключ], 0)) ), "ПВ", "ПНВ"), "НПВ")) -> НПВ | AK7: =IF( OR(Хронология[[#This Row],[Результат]]="ПВ", Хронология[[#This Row],[Результат]]="ПНВ"), Хронология[[#This Row],[Часы]] - IF( Хронология[[#This Row],[Результат]]="ПНВ", MAX(0, MAX(0, SUMIFS(Хронология[Часы], Хронология[Ключ], Хронология[[#This Row],[Ключ]], Хронология[Начало], "<=" & Хронология[[#This Row],[Начало]]) - IFERROR(INDEX(Планирование[Часы (план)], MATCH(Хронология[[#This Row],[Ключ]], Планирование[Ключ], 0)), 0)) - MAX(0, SUMIFS(Хронология[Часы], Хронология[Ключ], Хронология[[#This Row],[Ключ]], Хронология[Начало], "<" & Хронология[[#This Row],[Начало]]) - IFERROR(INDEX(Планирование[Часы (план)], MATCH(Хронология[[#This Row],[Ключ]], Планирование[Ключ], 0)), 0)) ), 0 ), 0 ) -> 0 | AL7: =IF( Хронология[[#This Row],[Результат]]="ПНВ", MAX(0, MAX(0, SUMIFS(Хронология[Часы], Хронология[Ключ], Хронология[[#This Row],[Ключ]], Хронология[Начало], "<=" & Хронология[[#This Row],[Начало]]) - IFERROR(INDEX(Планирование[Часы (план)], MATCH(Хронология[[#This Row],[Ключ]], Планирование[Ключ], 0)), 0)) - MAX(0, SUMIFS(Хронология[Часы], Хронология[Ключ], Хронология[[#This Row],[Ключ]], Хронология[Начало], "<" & Хронология[[#This Row],[Начало]]) - IFERROR(INDEX(Планирование[Часы (план)], MATCH(Хронология[[#This Row],[Ключ]], Планирование[Ключ], 0)), 0)) ), 0 ) -> 0 | AM7: =IF(Хронология[[#This Row],[Результат]]="НПВ", Хронология[[#This Row],[Часы]], 0) -> 3 | AN7: =SUMIFS(Хронология[НПВ], Хронология[Скважина], Хронология[[#This Row],[Скважина]], Хронология[Начало], "<=" & Хронология[[#This Row],[Начало]]) -> 9 | AO7: =SUMIFS(Хронология[ПНВ], Хронология[Скважина], Хронология[[#This Row],[Скважина]], Хронология[Начало], "<=" & Хронология[[#This Row],[Начало]]) -> 3.5 | AP7: =INT(ROUND(Хронология[[#This Row],[Начало]], 3)) -> 46146 | AQ7: =Хронология[[#This Row],[Начало]]-INT(Хронология[[#This Row],[Начало]]) -> 0 | AR7: =INT(ROUND(Хронология[[#This Row],[Окончание]], 3)) -> 46146 | AS7: =Хронология[[#This Row],[Окончание]]-INT(Хронология[[#This Row],[Окончание]]) -> 0.125 | AT7: =Хронология[[#This Row],[Мастер]] & CHAR(10) & Хронология[[#This Row],[Помощник мастера]] & CHAR(10) & Хронология[[#This Row],[Бурильщик]] -> Жабин П.П. Керимов Н.К. | AU7: =IF(Хронология[[#This Row],[Контекст простоя]]="Штатно", Хронология[[#This Row],[Скважина]] & " " & "ОК–" &Хронология[[#This Row],[ОК]] & " " & Хронология[[#This Row],[Этап]] & " " & Хронология[[#This Row],[Вид работ]] & " " & Хронология[[#This Row],[Объект работ]] & " " & Хронология[[#This Row],[Рейс]], Хронология[[#This Row],[Скважина]] & " " & "ОК–" &Хронология[[#This Row],[ОК]] & " " & Хронология[[#This Row],[Этап]] & " " & Хронология[[#This Row],[Контекст простоя]] & " " & Хронология[[#This Row],[Событие]] & " " & Хронология[[#This Row],[Вид работ]] & " " & Хронология[[#This Row],[Объект работ]] & " " & Хронология[[#This Row],[Рейс]]) -> 6 бис ОК– ПР Орг_простой Ожидание разрешения Устранение Предписания | AV7: =Хронология[[#This Row],[Результат]]&": "&Хронология[[#This Row],[Событие]]& CHAR(10) &Хронология[[#This Row],[Вид работ]]&" "&Хронология[[#This Row],[Объект работ]] -> НПВ: Ожидание разрешения Устранение Предписания | AW7: =SUMIF($AU$2:AU7, Хронология[[#This Row],[Ключ]], $AH$2:AH7) -> 0.375 | AX7: =Хронология[[#This Row],[Вид работ]] & " " & Хронология[[#This Row],[Объект работ]] -> Устранение Предписания
A8: ГДТ | B8: КРС | C8: Казанское | D8: 1 | E8: 6 бис | F8: Жабин П.П. | H8: Керимов Н.К. | I8: 1 | J8: 0.5 | L8: КРС | M8: Штатно | O8: Монтаж_демонтаж_установка | P8: Срыв | Q8: Объекты_устье | R8: Планшайба | T8: Подрыв ПШ (вес при подрыве ПШ 8,9тн). Разделка кабельного ввода. Протаскивание кабеля через КВ (L≈50м). Демонтаж КВ, ПШ. | U8: 5 | W8: Работы окончены | X8: Победит Холдинг | AE8: =IFERROR(IF(Хронология[[#This Row],[Забой, м]]-V7<0, 0, Хронология[[#This Row],[Забой, м]]-V7), 0) -> 0 | AF8: =AG7 -> 46146.125 | AG8: =Хронология[[#This Row],[Начало]]+Хронология[[#This Row],[Сутки]] -> 46146.333 | AH8: =Хронология[[#This Row],[Часы]]/24 -> 0.20833333 | AI8: =IFERROR(Хронология[[#This Row],[Сутки]]+AI7, Хронология[[#This Row],[Сутки]]) -> 1.5 | AJ8: =IF(Хронология[[#This Row],[Этап]]="Доп. работы", "ПВ", IFERROR( IF(AND( MATCH(Хронология[[#This Row],[Ключ]], Планирование[Ключ], 0), Хронология[[#This Row],[Подытог за операцию]] <= INDEX(Планирование[Сутки (план)], MATCH(Хронология[[#This Row],[Ключ]], Планирование[Ключ], 0)) ), "ПВ", "ПНВ"), "НПВ")) -> ПНВ | AK8: =IF( OR(Хронология[[#This Row],[Результат]]="ПВ", Хронология[[#This Row],[Результат]]="ПНВ"), Хронология[[#This Row],[Часы]] - IF( Хронология[[#This Row],[Результат]]="ПНВ", MAX(0, MAX(0, SUMIFS(Хронология[Часы], Хронология[Ключ], Хронология[[#This Row],[Ключ]], Хронология[Начало], "<=" & Хронология[[#This Row],[Начало]]) - IFERROR(INDEX(Планирование[Часы (план)], MATCH(Хронология[[#This Row],[Ключ]], Планирование[Ключ], 0)), 0)) - MAX(0, SUMIFS(Хронология[Часы], Хронология[Ключ], Хронология[[#This Row],[Ключ]], Хронология[Начало], "<" & Хронология[[#This Row],[Начало]]) - IFERROR(INDEX(Планирование[Часы (план)], MATCH(Хронология[[#This Row],[Ключ]], Планирование[Ключ], 0)), 0)) ), 0 ), 0 ) -> 1.48 | AL8: =IF( Хронология[[#This Row],[Результат]]="ПНВ", MAX(0, MAX(0, SUMIFS(Хронология[Часы], Хронология[Ключ], Хронология[[#This Row],[Ключ]], Хронология[Начало], "<=" & Хронология[[#This Row],[Начало]]) - IFERROR(INDEX(Планирование[Часы (план)], MATCH(Хронология[[#This Row],[Ключ]], Планирование[Ключ], 0)), 0)) - MAX(0, SUMIFS(Хронология[Часы], Хронология[Ключ], Хронология[[#This Row],[Ключ]], Хронология[Начало], "<" & Хронология[[#This Row],[Начало]]) - IFERROR(INDEX(Планирование[Часы (план)], MATCH(Хронология[[#This Row],[Ключ]], Планирование[Ключ], 0)), 0)) ), 0 ) -> 3.52 | AM8: =IF(Хронология[[#This Row],[Результат]]="НПВ", Хронология[[#This Row],[Часы]], 0) -> 0 | AN8: =SUMIFS(Хронология[НПВ], Хронология[Скважина], Хронология[[#This Row],[Скважина]], Хронология[Начало], "<=" & Хронология[[#This Row],[Начало]]) -> 9 | AO8: =SUMIFS(Хронология[ПНВ], Хронология[Скважина], Хронология[[#This Row],[Скважина]], Хронология[Начало], "<=" & Хронология[[#This Row],[Начало]]) -> 7.02 | AP8: =INT(ROUND(Хронология[[#This Row],[Начало]], 3)) -> 46146 | AQ8: =Хронология[[#This Row],[Начало]]-INT(Хронология[[#This Row],[Начало]]) -> 0.125 | AR8: =INT(ROUND(Хронология[[#This Row],[Окончание]], 3)) -> 46146 | AS8: =Хронология[[#This Row],[Окончание]]-INT(Хронология[[#This Row],[Окончание]]) -> 0.33333333 | AT8: =Хронология[[#This Row],[Мастер]] & CHAR(10) & Хронология[[#This Row],[Помощник мастера]] & CHAR(10) & Хронология[[#This Row],[Бурильщик]] -> Жабин П.П. Керимов Н.К. | AU8: =IF(Хронология[[#This Row],[Контекст простоя]]="Штатно", Хронология[[#This Row],[Скважина]] & " " & "ОК–" &Хронология[[#This Row],[ОК]] & " " & Хронология[[#This Row],[Этап]] & " " & Хронология[[#This Row],[Вид работ]] & " " & Хронология[[#This Row],[Объект работ]] & " " & Хронология[[#This Row],[Рейс]], Хронология[[#This Row],[Скважина]] & " " & "ОК–" &Хронология[[#This Row],[ОК]] & " " & Хронология[[#This Row],[Этап]] & " " & Хронология[[#This Row],[Контекст простоя]] & " " & Хронология[[#This Row],[Событие]] & " " & Хронология[[#This Row],[Вид работ]] & " " & Хронология[[#This Row],[Объект работ]] & " " & Хронология[[#This Row],[Рейс]]) -> 6 бис ОК– КРС Срыв Планшайба | AV8: =Хронология[[#This Row],[Результат]]&": "&Хронология[[#This Row],[Событие]]& CHAR(10) &Хронология[[#This Row],[Вид работ]]&" "&Хронология[[#This Row],[Объект работ]] -> ПНВ: Срыв Планшайба | AW8: =SUMIF($AU$2:AU8, Хронология[[#This Row],[Ключ]], $AH$2:AH8) -> 0.20833333 | AX8: =Хронология[[#This Row],[Вид работ]] & " " & Хронология[[#This Row],[Объект работ]] -> Срыв Планшайба
